<?xml version="1.0" encoding="utf-8"?>
<robot name="panda" xmlns:xacro="http://www.ros.org/wiki/xacro" path="assets/panda/panda.urdf">
	<link name="panda_link0">
		<inertial>
			<origin rpy="0 0 0" xyz="0 0 0.05"></origin>
			<mass value="2.9"></mass>
			<inertia ixx="0.1" ixy="0" ixz="0" iyy="0.1" iyz="0" izz="0.1"></inertia>
		</inertial>
		<visual>
			<geometry>
				<mesh filename="meshes/collision/link0.obj"></mesh>
			</geometry>
			<material name="panda_white">
				<color rgba="1. 1. 1. 1."></color>
			</material>
		</visual>
		<collision>
			<geometry>
				<sphere radius="0.118826"></sphere>
			</geometry>
			<origin xyz="-0.015957999999999993 -5.564999999999662e-05 0.0699902536" rpy="0 0 0"></origin>
		</collision>
		<collision>
			<geometry>
				<sphere radius="0.092724"></sphere>
			</geometry>
			<origin xyz="-0.08694099999999999 8.350000000003371e-06 0.042554253599999994" rpy="0 0 0"></origin>
		</collision>
	</link>
	<link name="panda_link1">
		<inertial>
			<origin rpy="0 0 0" xyz="0 -0.04 -0.05"></origin>
			<mass value="2.7"></mass>
			<inertia ixx="0.1" ixy="0" ixz="0" iyy="0.1" iyz="0" izz="0.1"></inertia>
		</inertial>
		<visual>
			<geometry>
				<mesh filename="meshes/visual/link1.obj"></mesh>
			</geometry>
			<material name="panda_white"></material>
		</visual>
		<collision>
			<geometry>
				<sphere radius="0.090742"></sphere>
			</geometry>
			<origin xyz="7.609999999999968e-05 -0.008377349999999995 -0.12724745" rpy="0 0 0"></origin>
		</collision>
		<collision>
			<geometry>
				<sphere radius="0.088878"></sphere>
			</geometry>
			<origin xyz="2.0999999999996716e-06 -0.048483349999999995 -0.019642450000000006" rpy="0 0 0"></origin>
		</collision>
	</link>
	<link name="panda_link2">
		<inertial>
			<origin rpy="0 0 0" xyz="0 -0.04 0.06"></origin>
			<mass value="2.73"></mass>
			<inertia ixx="0.1" ixy="0" ixz="0" iyy="0.1" iyz="0" izz="0.1"></inertia>
		</inertial>
		<visual>
			<geometry>
				<mesh filename="meshes/visual/link2.obj"></mesh>
			</geometry>
			<material name="panda_white"></material>
		</visual>
		<collision>
			<geometry>
				<sphere radius="0.080094"></sphere>
			</geometry>
			<origin xyz="-6.724999999999751e-05 -0.13901399999999997 0.0030911999999999884" rpy="0 0 0"></origin>
		</collision>
		<collision>
			<geometry>
				<sphere radius="0.081817"></sphere>
			</geometry>
			<origin xyz="-1.0249999999997525e-05 -0.05699299999999999 0.03771119999999999" rpy="0 0 0"></origin>
		</collision>
		<collision>
			<geometry>
				<sphere radius="0.077508"></sphere>
			</geometry>
			<origin xyz="2.3750000000002475e-05 -0.002010999999999999 0.052138199999999996" rpy="0 0 0"></origin>
		</collision>
	</link>
	<link name="panda_link3">
		<inertial>
			<origin rpy="0 0 0" xyz="0.01 0.01 -0.05"></origin>
			<mass value="2.04"></mass>
			<inertia ixx="0.1" ixy="0" ixz="0" iyy="0.1" iyz="0" izz="0.1"></inertia>
		</inertial>
		<visual>
			<geometry>
				<mesh filename="meshes/visual/link3.obj"></mesh>
			</geometry>
			<material name="panda_red">
				<color rgba="1. 1. 1. 1."></color>
			</material>
		</visual>
		<collision>
			<geometry>
				<sphere radius="0.082977"></sphere>
			</geometry>
			<origin xyz="0.0721216 0.0382319 -0.012539799999999997" rpy="0 0 0"></origin>
		</collision>
		<collision>
			<geometry>
				<sphere radius="0.083241"></sphere>
			</geometry>
			<origin xyz="0.006808599999999991 0.003882899999999998 -0.0667078" rpy="0 0 0"></origin>
		</collision>
	</link>
	<link name="panda_link4">
		<inertial>
			<origin rpy="0 0 0" xyz="-0.03 0.03 0.02"></origin>
			<mass value="2.08"></mass>
			<inertia ixx="0.1" ixy="0" ixz="0" iyy="0.1" iyz="0" izz="0.1"></inertia>
		</inertial>
		<visual>
			<geometry>
				<mesh filename="meshes/visual/link4.obj"></mesh>
			</geometry>
			<material name="panda_white"></material>
		</visual>
		<collision>
			<geometry>
				<sphere radius="0.086213"></sphere>
			</geometry>
			<origin xyz="-0.014967750000000005 0.01289864999999999 0.037483699999999995" rpy="0 0 0"></origin>
		</collision>
		<collision>
			<geometry>
				<sphere radius="0.081805"></sphere>
			</geometry>
			<origin xyz="-0.07700975000000002 0.06993564999999999 0.0030446999999999974" rpy="0 0 0"></origin>
		</collision>
	</link>
	<link name="panda_link5">
		<inertial>
			<origin rpy="0 0 0" xyz="0 0.04 -0.12"></origin>
			<mass value="3"></mass>
			<inertia ixx="0.1" ixy="0" ixz="0" iyy="0.1" iyz="0" izz="0.1"></inertia>
		</inertial>
		<visual>
			<geometry>
				<mesh filename="meshes/visual/link5.obj"></mesh>
			</geometry>
			<material name="panda_white"></material>
		</visual>
		<collision>
			<geometry>
				<sphere radius="0.077746"></sphere>
			</geometry>
			<origin xyz="5.449999999997371e-06 0.003668049999999999 -0.20817785" rpy="0 0 0"></origin>
		</collision>
		<collision>
			<geometry>
				<sphere radius="0.078297"></sphere>
			</geometry>
			<origin xyz="3.644999999999737e-05 0.03168405 -0.14633485000000002" rpy="0 0 0"></origin>
		</collision>
		<collision>
			<geometry>
				<sphere radius="0.07761"></sphere>
			</geometry>
			<origin xyz="5.244999999999737e-05 0.05063305 -0.06460185" rpy="0 0 0"></origin>
		</collision>
		<collision>
			<geometry>
				<sphere radius="0.070968"></sphere>
			</geometry>
			<origin xyz="6.044999999999737e-05 0.06153405 -0.0011348500000000067" rpy="0 0 0"></origin>
		</collision>
	</link>
	<link name="panda_link6">
		<inertial>
			<origin rpy="0 0 0" xyz="0.04 0 0"></origin>
			<mass value="1.3"></mass>
			<inertia ixx="0.1" ixy="0" ixz="0" iyy="0.1" iyz="0" izz="0.1"></inertia>
		</inertial>
		<visual>
			<geometry>
				<mesh filename="meshes/visual/link6.obj"></mesh>
			</geometry>
			<material name="panda_white"></material>
		</visual>
		<collision>
			<geometry>
				<sphere radius="0.083093"></sphere>
			</geometry>
			<origin xyz="0.08691892139339769 0.01211054120400112 0.0009217049781495377" rpy="0 0 0"></origin>
		</collision>
		<collision>
			<geometry>
				<sphere radius="0.074668"></sphere>
			</geometry>
			<origin xyz="0.009498921393397683 0.01031754120400112 0.019358704978149538" rpy="0 0 0"></origin>
		</collision>
	</link>
	<link name="panda_link7">
		<inertial>
			<origin rpy="0 0 0" xyz="0 0 0.08"></origin>
			<mass value=".2"></mass>
			<inertia ixx="0.1" ixy="0" ixz="0" iyy="0.1" iyz="0" izz="0.1"></inertia>
		</inertial>
		<visual>
			<geometry>
				<mesh filename="meshes/collision/link7.obj"></mesh>
			</geometry>
			<material name="panda_white"></material>
		</visual>
		<collision>
			<geometry>
				<sphere radius="0.049095"></sphere>
			</geometry>
			<origin xyz="0.03311775 0.03319985 0.08059375" rpy="0 0 0"></origin>
		</collision>
		<collision>
			<geometry>
				<sphere radius="0.053568"></sphere>
			</geometry>
			<origin xyz="-0.0005112499999999978 -0.001039149999999999 0.07940175000000001" rpy="0 0 0"></origin>
		</collision>
	</link>
	<link name="panda_link8">
		<inertial>
			<origin rpy="0 0 0" xyz="0 0 0"></origin>
			<mass value="0.0"></mass>
			<inertia ixx="0.1" ixy="0" ixz="0" iyy="0.1" iyz="0" izz="0.1"></inertia>
		</inertial>
	</link>
	<link name="panda_hand">
		<inertial>
			<origin rpy="0 0 0" xyz="0 0 0.04"></origin>
			<mass value=".81"></mass>
			<inertia ixx="0.1" ixy="0" ixz="0" iyy="0.1" iyz="0" izz="0.1"></inertia>
		</inertial>
		<visual>
			<geometry>
				<mesh filename="meshes/visual/hand.obj"></mesh>
			</geometry>
			<material name="panda_white"></material>
		</visual>
		<collision>
			<geometry>
				<sphere radius="0.04472"></sphere>
			</geometry>
			<origin xyz="9.994999999999897e-05 0.071274 0.0287947" rpy="0 0 0"></origin>
		</collision>
		<collision>
			<geometry>
				<sphere radius="0.050083"></sphere>
			</geometry>
			<origin xyz="2.094999999999897e-05 0.028428000000000002 0.0212437" rpy="0 0 0"></origin>
		</collision>
		<collision>
			<geometry>
				<sphere radius="0.049783"></sphere>
			</geometry>
			<origin xyz="4.94999999999897e-06 -0.018622 0.026521700000000002" rpy="0 0 0"></origin>
		</collision>
		<collision>
			<geometry>
				<sphere radius="0.040412"></sphere>
			</geometry>
			<origin xyz="-6.0500000000010305e-06 -0.07039100000000001 0.0347087" rpy="0 0 0"></origin>
		</collision>
		<collision>
			<geometry>
				<sphere radius="0.044048"></sphere>
			</geometry>
			<origin xyz="-0.00014405000000000103 -0.061794999999999996 0.0042407" rpy="0 0 0"></origin>
		</collision>
	</link>
	<link name="panda_leftfinger">
		<contact>
			<friction_anchor></friction_anchor>
			<stiffness value="30000.0"></stiffness>
			<damping value="1000.0"></damping>
			<spinning_friction value="0.1"></spinning_friction>
			<lateral_friction value="1.0"></lateral_friction>
		</contact>
		<inertial>
			<origin rpy="0 0 0" xyz="0 0.01 0.02"></origin>
			<mass value="0.1"></mass>
			<inertia ixx="0.1" ixy="0" ixz="0" iyy="0.1" iyz="0" izz="0.1"></inertia>
		</inertial>
		<visual>
			<geometry>
				<mesh filename="meshes/visual/finger.obj"></mesh>
			</geometry>
			<material name="panda_white"></material>
		</visual>
		<collision>
			<geometry>
				<sphere radius="0.018946"></sphere>
			</geometry>
			<origin xyz="-5.349999999999461e-06 0.0144523785 0.010577348" rpy="0 0 0"></origin>
		</collision>
		<collision>
			<geometry>
				<sphere radius="0.015906"></sphere>
			</geometry>
			<origin xyz="1.2650000000000538e-05 0.0116253785 0.026573348" rpy="0 0 0"></origin>
		</collision>
		<collision>
			<geometry>
				<sphere radius="0.015169"></sphere>
			</geometry>
			<origin xyz="-3.2349999999999465e-05 0.0088483785 0.042930348" rpy="0 0 0"></origin>
		</collision>
	</link>
	<link name="panda_rightfinger">
		<contact>
			<friction_anchor></friction_anchor>
			<stiffness value="30000.0"></stiffness>
			<damping value="1000.0"></damping>
			<spinning_friction value="0.1"></spinning_friction>
			<lateral_friction value="1.0"></lateral_friction>
		</contact>
		<inertial>
			<origin rpy="0 0 0" xyz="0 -0.01 0.02"></origin>
			<mass value="0.1"></mass>
			<inertia ixx="0.1" ixy="0" ixz="0" iyy="0.1" iyz="0" izz="0.1"></inertia>
		</inertial>
		<visual>
			<origin rpy="0 0 3.14159265359" xyz="0 0 0"></origin>
			<geometry>
				<mesh filename="meshes/visual/finger.obj"></mesh>
			</geometry>
			<material name="panda_white"></material>
		</visual>
		<collision>
			<geometry>
				<sphere radius="0.017622"></sphere>
			</geometry>
			<origin xyz="2.3350000003226916e-05 -0.009374378500001971 0.040003348" rpy="0 0 0"></origin>
		</collision>
		<collision>
			<geometry>
				<sphere radius="0.018946"></sphere>
			</geometry>
			<origin xyz="5.350000003226914e-06 -0.01445237850000197 0.010577348" rpy="0 0 0"></origin>
		</collision>
		<collision>
			<geometry>
				<sphere radius="0.016951"></sphere>
			</geometry>
			<origin xyz="-2.4649999996773085e-05 -0.01345537850000197 0.020969348" rpy="0 0 0"></origin>
		</collision>
	</link>
	<link name="panda_grasptarget">
		<inertial>
			<origin rpy="0 0 0" xyz="0 0 0"></origin>
			<mass value="0.0"></mass>
			<inertia ixx="0.1" ixy="0" ixz="0" iyy="0.1" iyz="0" izz="0.1"></inertia>
		</inertial>
	</link>
	<joint name="panda_joint1" type="revolute">
		<safety_controller k_position="100.0" k_velocity="40.0" soft_lower_limit="-2.8973" soft_upper_limit="2.8973"></safety_controller>
		<origin rpy="0 0 0" xyz="0 0 0.333"></origin>
		<parent link="panda_link0"></parent>
		<child link="panda_link1"></child>
		<axis xyz="0 0 1"></axis>
		<limit effort="87" lower="-2.9671" upper="2.9671" velocity="2.3925"></limit>
	</joint>
	<joint name="panda_joint2" type="revolute">
		<safety_controller k_position="100.0" k_velocity="40.0" soft_lower_limit="-1.7628" soft_upper_limit="1.7628"></safety_controller>
		<origin rpy="-1.57079632679 0 0" xyz="0 0 0"></origin>
		<parent link="panda_link1"></parent>
		<child link="panda_link2"></child>
		<axis xyz="0 0 1"></axis>
		<limit effort="87" lower="-1.8326" upper="1.8326" velocity="2.3925"></limit>
	</joint>
	<joint name="panda_joint3" type="revolute">
		<safety_controller k_position="100.0" k_velocity="40.0" soft_lower_limit="-2.8973" soft_upper_limit="2.8973"></safety_controller>
		<origin rpy="1.57079632679 0 0" xyz="0 -0.316 0"></origin>
		<parent link="panda_link2"></parent>
		<child link="panda_link3"></child>
		<axis xyz="0 0 1"></axis>
		<limit effort="87" lower="-2.9671" upper="2.9671" velocity="2.3925"></limit>
	</joint>
	<joint name="panda_joint4" type="revolute">
		<safety_controller k_position="100.0" k_velocity="40.0" soft_lower_limit="-3.0718" soft_upper_limit="-0.0698"></safety_controller>
		<origin rpy="1.57079632679 0 0" xyz="0.0825 0 0"></origin>
		<parent link="panda_link3"></parent>
		<child link="panda_link4"></child>
		<axis xyz="0 0 1"></axis>
		<limit effort="87" lower="-3.1416" upper="0.0873" velocity="2.3925"></limit>
	</joint>
	<joint name="panda_joint5" type="revolute">
		<safety_controller k_position="100.0" k_velocity="40.0" soft_lower_limit="-2.8973" soft_upper_limit="2.8973"></safety_controller>
		<origin rpy="-1.57079632679 0 0" xyz="-0.0825 0.384 0"></origin>
		<parent link="panda_link4"></parent>
		<child link="panda_link5"></child>
		<axis xyz="0 0 1"></axis>
		<limit effort="12" lower="-2.9671" upper="2.9671" velocity="2.8710"></limit>
	</joint>
	<joint name="panda_joint6" type="revolute">
		<safety_controller k_position="100.0" k_velocity="40.0" soft_lower_limit="-0.0175" soft_upper_limit="3.7525"></safety_controller>
		<origin rpy="1.57079632679 0 0" xyz="0 0 0"></origin>
		<parent link="panda_link5"></parent>
		<child link="panda_link6"></child>
		<axis xyz="0 0 1"></axis>
		<limit effort="12" lower="-0.0873" upper="3.8223" velocity="2.8710"></limit>
	</joint>
	<joint name="panda_joint7" type="revolute">
		<safety_controller k_position="100.0" k_velocity="40.0" soft_lower_limit="-2.8973" soft_upper_limit="2.8973"></safety_controller>
		<origin rpy="1.57079632679 0 0" xyz="0.088 0 0"></origin>
		<parent link="panda_link6"></parent>
		<child link="panda_link7"></child>
		<axis xyz="0 0 1"></axis>
		<limit effort="12" lower="-2.9671" upper="2.9671" velocity="2.8710"></limit>
	</joint>
	<joint name="panda_joint8" type="fixed">
		<origin rpy="0 0 0" xyz="0 0 0.107"></origin>
		<parent link="panda_link7"></parent>
		<child link="panda_link8"></child>
		<axis xyz="0 0 0"></axis>
	</joint>
	<joint name="panda_hand_joint" type="fixed">
		<parent link="panda_link8"></parent>
		<child link="panda_hand"></child>
		<origin rpy="0 0 -0.785398163397" xyz="0 0 0"></origin>
	</joint>
	<joint name="panda_finger_joint1" type="fixed">
		<parent link="panda_hand"></parent>
		<child link="panda_leftfinger"></child>
		<origin rpy="0 0 0" xyz="0 0.065 0.0584"></origin>
		<axis xyz="0 1 0"></axis>
	</joint>
	<joint name="panda_finger_joint2" type="fixed">
		<parent link="panda_hand"></parent>
		<child link="panda_rightfinger"></child>
		<origin rpy="0 0 0" xyz="0 -0.065 0.0584"></origin>
		<axis xyz="0 -1 0"></axis>
		<mimic joint="panda_finger_joint1"></mimic>
	</joint>
	<joint name="panda_grasptarget_hand" type="fixed">
		<parent link="panda_hand"></parent>
		<child link="panda_grasptarget"></child>
		<origin rpy="0 0 0" xyz="0 0 0.105"></origin>
	</joint>
</robot>