<?xml version="1.0" encoding="utf-8"?>
<robot name="scene">
	<link name="origin">
	</link>
	<link name="tabletop-internal-link">
		<visual>
			<geometry>
				<box size="1.0 2.0 0.019999999552965164"/>
			</geometry>
		</visual>
		<collision>
			<geometry>
				<box size="1.0 2.0 0.019999999552965164"/>
			</geometry>
		</collision>
	</link>
	<link name="o1-internal-link">
		<visual>
			<origin rpy="0 0 0" xyz="0 0 0.15000000596046448"/>
			<geometry>
				<cylinder radius="0.029999999329447746" length="0.30000001192092896"/>
			</geometry>
		</visual>
		<collision>
			<origin rpy="0 0 0" xyz="0 0 0.15000000596046448"/>
			<geometry>
				<cylinder radius="0.029999999329447746" length="0.30000001192092896"/>
			</geometry>
		</collision>
	</link>
	<link name="o11-internal-link">
		<visual>
			<origin rpy="0 0 0" xyz="0 0 0.15000000596046448"/>
			<geometry>
				<cylinder radius="0.03999999910593033" length="0.30000001192092896"/>
			</geometry>
		</visual>
		<collision>
			<origin rpy="0 0 0" xyz="0 0 0.15000000596046448"/>
			<geometry>
				<cylinder radius="0.03999999910593033" length="0.30000001192092896"/>
			</geometry>
		</collision>
	</link>
	<link name="o2-internal-link">
		<visual>
			<origin rpy="0 0 0" xyz="0 0 0.15000000596046448"/>
			<geometry>
				<cylinder radius="0.05000000074505806" length="0.30000001192092896"/>
			</geometry>
		</visual>
		<collision>
			<origin rpy="0 0 0" xyz="0 0 0.15000000596046448"/>
			<geometry>
				<cylinder radius="0.05000000074505806" length="0.30000001192092896"/>
			</geometry>
		</collision>
	</link>
	<link name="o3-internal-link">
		<visual>
			<geometry>
				<sphere radius="0.10999999940395355"/>
			</geometry>
		</visual>
		<collision>
			<geometry>
				<sphere radius="0.10999999940395355"/>
			</geometry>
		</collision>
	</link>
	<link name="o4-internal-link">
		<visual>
			<geometry>
				<sphere radius="0.10999999940395355"/>
			</geometry>
		</visual>
		<collision>
			<geometry>
				<sphere radius="0.10999999940395355"/>
			</geometry>
		</collision>
	</link>
	<link name="o5-internal-link">
		<visual>
			<origin rpy="0 0 0" xyz="0 0 0.15000000596046448"/>
			<geometry>
				<cylinder radius="0.029999999329447746" length="0.30000001192092896"/>
			</geometry>
		</visual>
		<collision>
			<origin rpy="0 0 0" xyz="0 0 0.15000000596046448"/>
			<geometry>
				<cylinder radius="0.029999999329447746" length="0.30000001192092896"/>
			</geometry>
		</collision>
	</link>
	<link name="o6-internal-link">
		<visual>
			<origin rpy="0 0 0" xyz="0 0 0.15000000596046448"/>
			<geometry>
				<cylinder radius="0.05000000074505806" length="0.30000001192092896"/>
			</geometry>
		</visual>
		<collision>
			<origin rpy="0 0 0" xyz="0 0 0.15000000596046448"/>
			<geometry>
				<cylinder radius="0.05000000074505806" length="0.30000001192092896"/>
			</geometry>
		</collision>
	</link>
	<link name="s0-internal-link">
		<visual>
			<origin rpy="0 0 0" xyz="0 0 0.1213500040970743"/>
			<geometry>
				<cylinder radius="0.08090000273138287" length="0.2427000081941486"/>
			</geometry>
		</visual>
		<collision>
			<origin rpy="0 0 0" xyz="0 0 0.1213500040970743"/>
			<geometry>
				<cylinder radius="0.08090000273138287" length="0.2427000081941486"/>
			</geometry>
		</collision>
	</link>
	<link name="s1-internal-link">
		<visual>
			<origin rpy="0 0 0" xyz="0 0 0.1213500040970743"/>
			<geometry>
				<cylinder radius="0.08090000273138287" length="0.2427000081941486"/>
			</geometry>
		</visual>
		<collision>
			<origin rpy="0 0 0" xyz="0 0 0.1213500040970743"/>
			<geometry>
				<cylinder radius="0.08090000273138287" length="0.2427000081941486"/>
			</geometry>
		</collision>
	</link>
	<link name="upper-link-internal-link">
		<visual>
			<origin rpy="0 0 0" xyz="0 0 0.25"/>
			<geometry>
				<cylinder radius="0.05000000074505806" length="0.5"/>
			</geometry>
		</visual>
		<collision>
			<origin rpy="0 0 0" xyz="0 0 0.25"/>
			<geometry>
				<cylinder radius="0.05000000074505806" length="0.5"/>
			</geometry>
		</collision>
	</link>
	<link name="e-internal-link">
		<visual>
			<origin rpy="0 0 0" xyz="0 0 0.16180000546276574"/>
			<geometry>
				<cylinder radius="0.08090000273138287" length="0.3236000109255315"/>
			</geometry>
		</visual>
		<collision>
			<origin rpy="0 0 0" xyz="0 0 0.16180000546276574"/>
			<geometry>
				<cylinder radius="0.08090000273138287" length="0.3236000109255315"/>
			</geometry>
		</collision>
	</link>
	<link name="e-link-internal-link">
		<visual>
			<origin rpy="0 0 0" xyz="0 0 0.25"/>
			<geometry>
				<cylinder radius="0.05000000074505806" length="0.5"/>
			</geometry>
		</visual>
		<collision>
			<origin rpy="0 0 0" xyz="0 0 0.25"/>
			<geometry>
				<cylinder radius="0.05000000074505806" length="0.5"/>
			</geometry>
		</collision>
	</link>
	<link name="w0-internal-link">
		<visual>
			<origin rpy="0 0 0" xyz="0 0 0.1213500040970743"/>
			<geometry>
				<cylinder radius="0.05000000074505806" length="0.2427000081941486"/>
			</geometry>
		</visual>
		<collision>
			<origin rpy="0 0 0" xyz="0 0 0.1213500040970743"/>
			<geometry>
				<cylinder radius="0.05000000074505806" length="0.2427000081941486"/>
			</geometry>
		</collision>
	</link>
	<link name="w1-internal-link">
		<visual>
			<origin rpy="0 0 0" xyz="0 0 0.1213500040970743"/>
			<geometry>
				<cylinder radius="0.05000000074505806" length="0.2427000081941486"/>
			</geometry>
		</visual>
		<collision>
			<origin rpy="0 0 0" xyz="0 0 0.1213500040970743"/>
			<geometry>
				<cylinder radius="0.05000000074505806" length="0.2427000081941486"/>
			</geometry>
		</collision>
	</link>
	<link name="w2-internal-link">
		<visual>
			<origin rpy="0 0 0" xyz="0 0 0.1213500040970743"/>
			<geometry>
				<cylinder radius="0.05000000074505806" length="0.2427000081941486"/>
			</geometry>
		</visual>
		<collision>
			<origin rpy="0 0 0" xyz="0 0 0.1213500040970743"/>
			<geometry>
				<cylinder radius="0.05000000074505806" length="0.2427000081941486"/>
			</geometry>
		</collision>
	</link>
	<link name="end-internal-link">
		<visual>
			<origin rpy="0 0 0" xyz="0 0 0.1213500040970743"/>
			<geometry>
				<cylinder radius="0.015000000819563875" length="0.2427000081941486"/>
			</geometry>
		</visual>
		<collision>
			<origin rpy="0 0 0" xyz="0 0 0.1213500040970743"/>
			<geometry>
				<cylinder radius="0.015000000819563875" length="0.2427000081941486"/>
			</geometry>
		</collision>
	</link>
	<link name="end-link-internal-link">
		<visual>
			<origin rpy="0 0 0" xyz="0 0 0.009999999776482582"/>
			<geometry>
				<cylinder radius="0.07999999821186066" length="0.019999999552965164"/>
			</geometry>
		</visual>
		<collision>
			<origin rpy="0 0 0" xyz="0 0 0.009999999776482582"/>
			<geometry>
				<cylinder radius="0.07999999821186066" length="0.019999999552965164"/>
			</geometry>
		</collision>
	</link>
	<joint name="tabletop" type="fixed">
		<parent link="origin"/>
		<child link="tabletop-internal-link"/>
		<origin rpy="0.0 0.0 0.0" xyz="0.0 0.0 0.0"/>
	</joint>
	<joint name="o1" type="fixed">
		<parent link="tabletop-internal-link"/>
		<child link="o1-internal-link"/>
		<origin rpy="0.0 0.0 0.0" xyz="0.009999999776482582 0.1599999964237213 0.0"/>
	</joint>
	<joint name="o11" type="fixed">
		<parent link="tabletop-internal-link"/>
		<child link="o11-internal-link"/>
		<origin rpy="0.0 0.0 0.0" xyz="0.20999999344348907 0.14000000059604645 0.0"/>
	</joint>
	<joint name="o2" type="fixed">
		<parent link="tabletop-internal-link"/>
		<child link="o2-internal-link"/>
		<origin rpy="0.0 0.0 0.0" xyz="0.18000000715255737 0.33500000834465027 0.0"/>
	</joint>
	<joint name="o3" type="fixed">
		<parent link="tabletop-internal-link"/>
		<child link="o3-internal-link"/>
		<origin rpy="0.0 0.0 0.0" xyz="0.0 0.3499999940395355 0.10999999940395355"/>
	</joint>
	<joint name="o4" type="fixed">
		<parent link="tabletop-internal-link"/>
		<child link="o4-internal-link"/>
		<origin rpy="0.0 0.0 0.0" xyz="-0.10000000149011612 -0.25 0.10999999940395355"/>
	</joint>
	<joint name="o5" type="fixed">
		<parent link="tabletop-internal-link"/>
		<child link="o5-internal-link"/>
		<origin rpy="0.0 0.0 0.0" xyz="0.18000000715255737 0.5350000262260437 0.0"/>
	</joint>
	<joint name="o6" type="fixed">
		<parent link="tabletop-internal-link"/>
		<child link="o6-internal-link"/>
		<origin rpy="0.0 0.0 0.0" xyz="-0.2800000011920929 0.33500000834465027 0.0"/>
	</joint>
	<joint name="s0" type="revolute">
		<parent link="tabletop-internal-link"/>
		<child link="s0-internal-link"/>
		<origin rpy="0.0 0.0 0.0" xyz="0.0 -0.5 0.0"/>
		<axis xyz="0 0 1"/>
		<limit effort="1.0" lower="-3.14159" upper="3.14159" velocity="1.0"/>
	</joint>
	<joint name="s1" type="revolute">
		<parent link="s0-internal-link"/>
		<child link="s1-internal-link"/>
		<origin rpy="0.0 1.5707499980926187 0.0" xyz="0.0 0.0 0.16180000546276574"/>
		<axis xyz="0 0 1"/>
		<limit effort="1.0" lower="-3.14159" upper="3.14159" velocity="1.0"/>
	</joint>
	<joint name="upper-link" type="fixed">
		<parent link="s1-internal-link"/>
		<child link="upper-link-internal-link"/>
		<origin rpy="0.0 -1.5707499980926187 0.0" xyz="0.0 0.0 0.16180000546276574"/>
	</joint>
	<joint name="e" type="revolute">
		<parent link="upper-link-internal-link"/>
		<child link="e-internal-link"/>
		<origin rpy="0.0 -1.5707499980926187 0.0" xyz="0.08090000273138287 0.0 0.5"/>
		<axis xyz="0 0 1"/>
		<limit effort="1.0" lower="-3.14159" upper="3.14159" velocity="1.0"/>
	</joint>
	<joint name="e-link" type="fixed">
		<parent link="e-internal-link"/>
		<child link="e-link-internal-link"/>
		<origin rpy="0.0 1.5707499980926187 0.0" xyz="0.0 0.0 0.2427000081941486"/>
	</joint>
	<joint name="w0" type="revolute">
		<parent link="e-link-internal-link"/>
		<child link="w0-internal-link"/>
		<origin rpy="0.0 -1.5707499980926187 0.0" xyz="0.16180000546276574 0.0 0.5"/>
		<axis xyz="0 0 1"/>
		<limit effort="1.0" lower="-3.14159" upper="3.14159" velocity="1.0"/>
	</joint>
	<joint name="w1" type="revolute">
		<parent link="w0-internal-link"/>
		<child link="w1-internal-link"/>
		<origin rpy="0.0 -1.5707499980926187 0.0" xyz="0.16180000546276574 0.0 0.0"/>
		<axis xyz="0 0 1"/>
		<limit effort="1.0" lower="-3.14159" upper="3.14159" velocity="1.0"/>
	</joint>
	<joint name="w2" type="fixed">
		<parent link="w1-internal-link"/>
		<child link="w2-internal-link"/>
		<origin rpy="0.0 1.5707499980926187 0.0" xyz="-0.1213500040970743 0.0 0.0"/>
	</joint>
	<joint name="end" type="fixed">
		<parent link="w2-internal-link"/>
		<child link="end-internal-link"/>
		<origin rpy="0.0 0.0 0.0" xyz="0.0 0.0 -0.08090000273138287"/>
	</joint>
	<joint name="end-link" type="fixed">
		<parent link="end-internal-link"/>
		<child link="end-link-internal-link"/>
		<origin rpy="0.0 0.0 0.0" xyz="0.0 0.0 0.0"/>
	</joint>
</robot>